INFO:root:Executed R('load(\'../../instructor/assignments/lab7/lab7-tests2.rda\')')
INFO:root:Executed R('set.seed(47)')
INFO:root:Executed R('datagenerator.t1 <- dataGenerator(1:10, 2, 2)')
INFO:root:(2 points) R('10 == length(datagenerator.t1)')[0] is True
INFO:root:(2 points) R('grade.l7$datagenerator.t1 == datagenerator.t1')[0] is True
INFO:root:Executed R('set.seed(47)')
INFO:root:Executed R('datagenerator.t2 <- dataGenerator(cbind(c(1, 2, 3), c(4, 1, 5)), c(2, 4), 2)')
INFO:root:(2 points) R('all.equal(grade.l7$datagenerator.t2, datagenerator.t2)')[0] is True
INFO:root:Executed R('set.seed(47)')
INFO:root:Executed R('betaestimator.t1 <- betaEstimator(1:10, 2, 2)')
INFO:root:(2 points) R('1 == length(betaestimator.t1)')[0] is True
INFO:root:(2 points) R('grade.l7$betaestimator.t1 == betaestimator.t1')[0] is True
INFO:root:Executed R('set.seed(47)')
INFO:root:Executed R('betaestimator.t2 <- betaEstimator(cbind(rnorm(10), rnorm(10)), c(2, 4), 2)')
INFO:root:(2 points) R('2 == length(betaestimator.t2)')[0] is True
INFO:root:(2 points) R('all.equal(grade.l7$betaestimator.t2, betaestimator.t2)')[0] is True
INFO:root:(2 points) R('grade.l7$betavariance.t1 == betaVariance(lab7$predictors, 4)')[0] is True
INFO:root:(2 points) R('grade.l7$betavariance.t2 == betaVariance(1:10, 2)')[0] is True
ERROR:root:(2 points) Checking R('length(X) == 100')[0]
ERROR:root:... Expecting: True
ERROR:root:... But got:   Traceback error
ERROR:root:Got exception:
Traceback (most recent call last):
  File "/Users/Karl/anaconda/lib/python2.7/site-packages/gradebook/score.py", line 180, in check
    result = eval(command, g)
  File "<string>", line 1, in <module>
  File "/Users/Karl/anaconda/lib/python2.7/site-packages/rpy2/robjects/__init__.py", line 248, in __call__
    res = self.eval(p)
  File "/Users/Karl/anaconda/lib/python2.7/site-packages/rpy2/robjects/functions.py", line 166, in __call__
    return super(SignatureTranslatedFunction, self).__call__(*args, **kwargs)
  File "/Users/Karl/anaconda/lib/python2.7/site-packages/rpy2/robjects/functions.py", line 99, in __call__
    res = super(Function, self).__call__(*new_args, **new_kwargs)
RRuntimeError: Error in eval(expr, envir, enclos) : object 'X' not found

ERROR:root:Traceback (most recent call last):
  File "/Users/Karl/anaconda/lib/python2.7/site-packages/gradebook/score.py", line 180, in check
    result = eval(command, g)
  File "<string>", line 1, in <module>
  File "/Users/Karl/anaconda/lib/python2.7/site-packages/rpy2/robjects/__init__.py", line 248, in __call__
    res = self.eval(p)
  File "/Users/Karl/anaconda/lib/python2.7/site-packages/rpy2/robjects/functions.py", line 166, in __call__
    return super(SignatureTranslatedFunction, self).__call__(*args, **kwargs)
  File "/Users/Karl/anaconda/lib/python2.7/site-packages/rpy2/robjects/functions.py", line 99, in __call__
    res = super(Function, self).__call__(*new_args, **new_kwargs)
RRuntimeError: Error in eval(expr, envir, enclos) : object 'X' not found

Traceback (most recent call last):
  File "/Users/Karl/anaconda/lib/python2.7/site-packages/gradebook/score.py", line 180, in check
    result = eval(command, g)
  File "<string>", line 1, in <module>
  File "/Users/Karl/anaconda/lib/python2.7/site-packages/rpy2/robjects/__init__.py", line 248, in __call__
    res = self.eval(p)
  File "/Users/Karl/anaconda/lib/python2.7/site-packages/rpy2/robjects/functions.py", line 166, in __call__
    return super(SignatureTranslatedFunction, self).__call__(*args, **kwargs)
  File "/Users/Karl/anaconda/lib/python2.7/site-packages/rpy2/robjects/functions.py", line 99, in __call__
    res = super(Function, self).__call__(*new_args, **new_kwargs)
RRuntimeError: Error in eval(expr, envir, enclos) : object 'X' not found

INFO:root:(2 points) R('length(beta.hats) == 1000')[0] is True
INFO:root:(3 points) R('grade.l7$betahats.t == beta.hats')[0] is True
INFO:root:(2 points) R('prop.2sd>=0 & prop.2sd <=1')[0] is True
INFO:root:(3 points) R('0.96 == prop.2sd')[0] is True
INFO:root:You got a 28 out of 30.
